Workbook
Name NamedRange1: 'JON EVENTS'!$C:$C
Name NamedRange1: EVENTS!$C:$C

Sheet GLOSSARY
A1: PERSON ID | B1: NAME | C1: OTHER NAMES | D1: ETHNICITY/NATIONALITY | E1: PHYSICAL DESCRIPTORS | F1: LOCATION(S) | G1: LOCATION IDS | H1: BIOGRAPHICAL INFORMATION
A2: P1 | B2: MOLIA | C2: COOBAH CUBBAH | D2: EBO | E2: 4'6 INCHES HIGH (1761) 'TT' IN DOWNWARD TRIANGLE BRAND ON HER RIGHT SHOULDER (1761) BRAND ON HER FOREHEAD (1770) CHAIN/COLLAR MARKS AND SCARS ON HER NECK/SHOULDERS SCARS FROM REPEATED FLOGGINGS | F2: EGYPT ESTATE (1761-1767) BREADNUT ISLAND PEN (1767-1774) | G2: L1; L3 | H2: Molia first appeared in the diary in December of 1761. Thistlewood purchased her in a group sale of five other Africans from a trader for 50 pounds. Upon her arrival to Egypt estate, he paired her with an enslaved fieldwoman named Wonga (also known as Princess) to be 'seasoned'. One week after her purchase, he put her to work in Egypt's fields. Four years following her purchase, Molia gave birth to a mixed race baby girl named Silvia. When Silvia was fifteen months old, Thistlewood hired Molia to labor on Masemure, a neighboring sugar plantation. He forced her to leave Silvia behind and in the care of Nanny, another enslaved mother of a little girl named Little Phibbah who was the same age as Silvia. Shortly after their separation, Silvia fell sick and died. Molia was never the same following Silvia's death. She never had any more children, and and she also refused to stay in place. Over the course of the next six years, she would run away no less than fourteen times. The seventh of these escapes was to a place called Bluefields Bay, to see a person Molia herself identified as a "Shipmate," a person who had survived the Middle Passage voyage with her to Jamaica. The fourteenth of these escapes (and the last that she would make in Jamaica) was to an estate called Paradise; it was the same estate where Molia had been sent to give birth to Silvia. Following this fourteenth recapture, Thistlewood sold Molia to another slave owner, who transported her away from Jamaica, and to the British colony of Savannah. Georgia.
A3: P2 | B3: SILVIA | D3: HALF EBO MOST LIKELY MIXED RACE | E3: FAIRSKINNED;'MULATTO' (1766) | F3: EGYPT ESTATE (1766) BREADNUT ISLAND PEN (1767-1768) | G3: L1; L3 | H3: Silvia was born on November 12, 1766. Her mother was Molia, an "Ebo" woman presumed to have been 15 at the time of her capture into the slave trade, and 20 at the time of her birth. Silvia's father was never identified, although he was presumed by Thistlewood to have been a white man. Her mother was assisted in the delivery by an enslaved grannie named Paradise Quasheba. For the first fifteen months of her life Silvia lived with her mother, and another enslaved young African woman named Peggy. In the winter of 1768, Thistlewood contracted Molia out to labor on a neighboring sugar estate named Masemure. He forced Molia to leave Silvia behind and in the care of another enslaved woman named Nanny, who also had a 1 year old daughter named Little Phibbah. Several months after her mother's departure, Silvia became sick of an unknown illness, and died at just fifteen months old.
A4: P3 | B4: EGYPT LUCY | D4: ? | F4: EGYPT ESTATE (1750-1772) | G4: L1 | H4: Egypt Lucy was an Afro-Creole woman who labored on Egypt Estate's First gang for much of her life. She had two primary domestic partners: Daniel, a skilled enslaved laborer who lived on Egypt, and Mason Quashe a skilled enslaved laborer who belonged to Elizabeth Anderson--the quadroon mistress of William Dorrill, Thistlewood's first employer-- and who was a regular visitor at Egypt to perform various tasks of carpentry, masonry, and even supervision of the First Gang. Between 1750 and her death in 1772, Egypt Lucy had three confirmed pregnancies: one in October 1754 to her daughter Julina with Daniel, the second in August of 1758 to an unnamed son (presumably also with Daniel) who died at just 5 days old, and the third in November of 1759 to a son who was named Little Quashe (presumably after his father, Mason Quashe). In May 1760, Egypt became the wet nurse to John, the son of Egypt's housekeeper and Thistlewood. This seemed to mark the beginining of a strong and lasting friendship between not only Egypt Lucy and Phibbah, but between Egypt Lucy and Phibbah's broader social network of enslaved domestic workers. This circle included Phibbah's sister, Nancy,her daughter Accubah, an enslaved healer woman named Vine, and another enslaved domestic worker called House Franke. Together, the six women formed an agricutural co-op of sorts, pooling the money and resources they earned through the selling of goods they raised from their provison grounds, their raising of livestock, and from sewing work they were contracted to perform for whites. They intended the funds to be used to purchase at least one of each other's freedom. Egypt Lucy was relatively prosperous as a enslaved business woman; such that in 1769, she along with Phibbah, and House Franke gave Thistlewood a 27 pound loan to help him in his transition from Egypt's overseer to an independeny penkeeper of a property called Breadnut Island Pen. EGypt Lucy would als give Thistlewood a second personal loan of 10 pounds; he would go on to repay both loans within about a year. Following her stint as John's wetnurse, Egypt Lucy continued to act as a care provider and parental influence for both Phibbah's children. When Phibbah and Thistlewood moved away from Egypt and left John behind, they entrusted EGypt Lucy to escort him to their newhome on Breadnut Islabd Pen for visits. Egypt Lucy also kept abreast of the day-to-day and night-to-night activities of Phibbah's daughter Accubah--including her covert fasincination and involvement in the secret Myal society. On multiple occasions throughout the years, Egypt Lucy was chosen by her white masters to be a 'seasoner,' a role designed for mostly Afro-Creole enslaved men and women who had either been born or resided in Jamaica for extended periods of time to acclimate/'season' newly arrived Africans to their new realities. In December of 1761, after purchasing 6 new Africans from a slave trader named John Hutt, Thistlewood tasked Egpyt Lucy with being the seasoner of a young African girl included in this sale named Ogo (he would rename her Maria). In November of 1766, Ogo would give birth to her first child: a daughter named Lucy. In July 1770, shortly following Molia's fourth escape from and return to Breadnut Island Pen, Egypt Lucy paid a visit to the pen, where she interrupted Thistlewood's attempt to punish Molia by confining her to a set of bilboes, convincing him not to. As a field laborer, Egypt Lucy was frequently in poor health. In June of 1772, she died. Phibbah and a 12 year old John attended her funeral and burial.
A5: P4 | B5: JULINA | D5: ? | F5: EGYPT ESTATE (1750--?) | G5: L1 | H5: Julina was born in October of 1754 on Egypt Estate. Her mother was Egypt Lucy, an enslaved and Afro-Creole member Egypt estate's first gang. Her father was Daniel, an enslaved skilled laborer who also lived on Egypt. In August of 1758, Julina's mother Egypt Lucy gave birth to an unnamed baby boy, Julina's brother, who died at 5 days old. The following year, in November of 1759, Egypt Lucy was sent away from Egypt to a neighboring estate called Paradise, where she gave birth to another son, Julina's second brother, who was named Little Quashe. Julina fell sick while her mother was away, but soon recovered. Little Quashe and Egypt Lucy returned to Egypt in January of 1760, where they would continue as one nuclear household. In October of 1766, Julina would, for reasons unspecified by Thistlewood, accompany Molia to Paradise for her lying in period before she gave birth to Silvia in November of that same year. In December of 1770, Julina became the mistress/concubine of a white man named Robert Parker, a friend of Thistlewood's.
A6: P5 | B6: LITTLE QUASHE | D6: ? | F6: EGYPT ESTATE (1759--?) | G6: L1 | H6: Little Quashe was born in November of 1759, the son of Egypt Lucy, a field laborer of Egypt Estate and Mason Quashe, a skilled enslaved laborer who belonged to Elizabeth Anderson--the quadroon mistress of William Dorrill, Thistlewood's first employer-- and who was a regular visitor at Egypt to perform various tasks of carpentry, masonry, and even supervision of the First Gang. He was half-brother to Julina, Egypt Lucy's first daughter. Like many children of his time and place, Little Quashe was frequently ill. He was cared for by his mother, as well as by his mother's close friends, Phibbah (the housekeeper of Egypt Estate), and Vine, an enslaved woman, healer and storyteller from a neighboring estate.
A7: P6 | B7: ABBA | D7: AFRICAN | F7: EGYPT ESTATE (1758--1767) BREADNUT ISLAND PEN (1767-1786) | G7: L1; L3 | H7: Abba was an enslaved African young woman, first appearing in the diary in Februaryof 1758 when she was purchased by Thistlewood from a slave trader named John Parkinson for 46 pounds. Thistlewood intended for her to be a domestic worker, setting her to train in the cookroom with Egypt's housekeeper Phibbah, then hiring her out to other white neighbors throughout the parish. Abba would have several domestic/sexual partners over the course of the twenty eight years she appears in the diaries. The first of these was Hazat, a driver who belonged to William Mould, an owner of a neighboring plantation. Another was Cudjoe, an enslaved fieldhand who belonged to John Rickett, one of Thistlewood's friends. A third was Neptune, an enslaved man who belonged to a Savanna la Mar tavern owner and another of Thistlewood's friends, Thomas Emotson. A fourth was Lincoln, the very first enslaved person Thistlewood ever purcahsed. Abba was unique among the many enslaved women who appear in the diairies in the sense that was extremely fertile, having a total of thirteen pregnancies over the span of twenty eight years. Ten of these resulted in live births, one in a stillbirth. Of these ten children, six (Including Johnie, Neptune, Jenny, Mary)survived their first year of life and four survived until at least 1786, the year of Thistlewood's death and the last year of the diary records. Abba and her children's living arrangements fluctuated usually depending upon who her current sexual/domestic partner was, but for a period of time in 1767, she and Mary, Johnie and Neptune lived with Sally, a Congo woman who Thistlewood had first purchased as a 8 or 9 year old child in 1762. Abba was known to tell the Anansi spider stories that she had learned from her homeland alongside Vine, an enslaved domestic woman and healer from a neighboring plantation called Cabaritta Estate. Abba would be one of the enslaved people on Breadnut Island Pen who would go on to outlive Thistlewood following his death in 1786. In a 1787 appraisal of his human property, her age was described as "unknown", and she was valued at 40 pounds.
A8: P7 | B8: PHIBBAH | C8: PHIB; PHIBBAH | D8: ? | F8: EGYPT ESTATE (?--1767) PARADISE ESTATE SALT RIVER ESTATE BREADNUT ISLAND PEN (1767-1786) | G8: L1; L2; L3; L4 | H8: Phibbah was the Afro-Creole housekeeper of Egypt Estate. She was owned by Molly Cope, the wife of John Cope, Thistlewood's employer. A prominent and influential figure among the broader enslaved communit, Phibbah often leveraged that influence to gain relative material and social benefits for herself, her children and her other loved ones. Phibbah was very close with a sister named Nancy who lived on a neighboring plantation and very frequently visited her. Phibbah had an unnamed enslaved husband, but this relationship was soon displaced by the sexual/domestic relationship she would strike up with Thistlewood that would last for over three decades, ending only in his death in 1786. Although he was never monogamous, Thistlewood referred to Phibbah as his "wife". The diaries depict Phibbah as having three confirmed pregnancies/children. The first was a daughter named Accubah [unknown date of birth and father; also called Coobah and later Jenny Young], a stillborn boy [with John Cope, born ] and John [her son with Thistlewood who lived to the age of 20]. Phibbah had a tight knit circle of friends, most of whom were enslaved women domestic laborers. These included her sister Nancy, her daughter Accubah, domestic laborer and healer Vine, and domestic laborer House Franke. Following the birth of her son John in 1760, she also became very close friends with an enslaved field woman of Egypt estate called Egypt Lucy who served as John's wetnurse. Phibbah often visited with Egypt Lucy, cared for her son Little Quashe when he was will. She also brought Egypt Lucy into the agricultural co-op network that she had formed with her sister, daughter and other friends. Together, the six women pooled the money and resources they earned through the selling of goods they raised from their provison grounds, their raising of livestock, and from sewing work they were contracted to perform for whites. They intended the funds to be used to purchase at least one of each other's freedom. Phibbah was a very prosperous businesswoman and in 1769, she along with Egypt Lucy, and House Franke gave Thistlewood a 27 pound loan to help him in his transition from Egypt's overseer to an independent penkeeper of a property called Breadnut Island Pen-- a loan that he would return about a year or so later. It was one of several loans she would give to them him throughout their relationship. Phibbah outlived Thistlewood, and was granted her freedom following his death in 1786.
A9: P8 | B9: NANCY | D9: ? | F9: PARADISE ESTATE (1750-1786) | G9: L2 | H9: Nancy was an Afro-Creole domestic laborer who lived on/moved between Egypt estate, as well as Paradise estate (another plantation owned by John Cope. She was the sister of Phibbah, Egypt's housekeeper, and aunt to Phibbah's two children, Accubah [also known as Coobah and later Jenny Young] and John. The diaries confirm Nancy as having two pregnancies; one in to a boy named Davie who fell sick snd died in 1756, and another in 1757 to a girl who was born dead. Like Phibbah, Nancy held relative measures of material and social privilege. She held multiple 'balls' that her sister and other domestic enslaved labrers and whites attended. She was able to 'rent' out the labor of an enslaved Egypt fieldwoman named Rose to assist her in caring for Davie when he was ill. In the aftermath of Davie's death, Nancy held a "play" (funeral) for Davie that lasted for two days/nights. Nancy was close friends with her sister Phibbah, as well as a broader circle of friends that included ncluded her sister Phibbah, her niece Accubah, domestic laborer and healer Vine, domestic laborer House Franke, and fieldwoman Egypt Lucy. Together, the six women pooled the money and resources they earned through the selling of goods they raised from their provison grounds, their raising of livestock, and from sewing work they were contracted to perform for whites. They intended the funds to be used to purchase at least one of each other's freedom (notably, Nancy's).
A10: P9 | B10: JOHN | C10: MULATTO JOHN PHIBBAH'S JOHN | D10: MIXED RACE | E10: FAIR SKINNED; 'MULATTO' | F10: EGYPT ESTATE (1760) MRS BENNETT'S | G10: L1; L18 | H10: John was the mixed race son of Phibbah, the housekeeper of Egypt Estate, and Thomas Thistlewood, Egypt's overseer and the later owner of Breadnut Island Pen. Although he assumed paternal and financial support for him, Thistlewood never directly acknowledged paternity of John in the diaries, either referring to him as "Phibbah's child" or "Mulatto John". John was born in April of 1760 in a difficult birth, assisted by a midwife from Salt River estate called Old Daphne and House Franke, his mother's close friend and business partner. In the days following his birth, John was nursed by an Egypt fieldwoman named Egypt Lucy, who would go on to become one of his mother's closest friends, business partners, and a caregiver for John when his parents moved away from him. Phibbah secured a promise from Thistlewood in October of 1761 that John would be granted his freedom and in May of 1762, he fulfilled that promise. During the majority of his childhood, the freed John was sent to live in a boarding school for mixed race children where he learned how to read and write, was eventually apprenticed to become a carpenter at the age of 15, and allowed to join in Jamaica's 'colored' militia. One of his childhood friends was James, the son of a mixed race domestic laborer named Little Mimber on a neighboring plantation. John was not diligent in his apprenticeship, often absenting from work for days on end. He was frequently in debt, and involved in domestic disputes. John lived to the age of twenty, then died in September of 1780 of a sudden, putrid stomach infection that turned his fingernails black and shredded his intestines. Phibbah was beside herself with grief, later suspecting that he had been willfully poisoned as a result of a love triangle gone horribly wrong. The death struck a heavy blow to the broader enslaved community, many of whom came to his burial. John’s half-sister Accubah came to stay with their mother for several weeks afterwards.
A11: P10 | B11: HOUSE FRANKE | D11: ? | F11: PARADISE ESTATE | G11: L2 | H11: House Franke was an enslaved domestic laborer who lived on Paradise estate. She was a very close friend of Phibbah [the housekeeper of Egypt estate], Phibbah's sister Nancy, Phibbah's daughter Accubah [also known as Coobah and later, Jenny Young], an enslaved domestic laborer and healer named Vine, and an enslaved Egypt fieldwoman named Egypt Lucy. Together, the six women pooled the money and resources they earned through the selling of goods they raised from their provison grounds, their raising of livestock, and from sewing work they were contracted to perform for whites. They intended the funds to be used to purchase at least one of each other's freedom. House Franke had a husband named Paradise Jack who (presumably) lived with her at Paradise. House Franke was a very frequent visitor to Egypt, and to Breadnut Island Pen to visit with Phibbah. When Phibbah gave birth to John in 1760, House Franke came and stayed at Egypt for several days to assist at her bedside. When Phibbah herself fell ill, House Franke came and stayed with her again to nurse her back to health. Like Egypt Lucy, House Franke also mantained a significant presence in the lives of Phbbah's children (who did not live with her for the majority of the time). House Franke was a relatively prosperous businessowman and in 1769, she along with Phibbah, and Egypt Lucy gave Thistlewood a 27 pound loan to help him in his transition from Egypt's overseer to an independeny penkeeper of a property called Breadnut Island Pen. He would repay the loan about a year later. House Franke made a second loan to Thistlewood in December of 1770; he repaid it in September of 1771.
A12: P11 | B12: OLD DAPHNE | D12: ? | F12: SALT RIVER ESTATE | G12: L4 | H12: Old Daphne was an enslaved 'grannie' midwife who resided on Salt River Estate. She was called to preside over at least fivw different childbirths over the course of about a decade, including Phibbah, the housekeeper of Egypt estate and three enslaved fieldwomen named Jenny, Anjaw, Mountain Lucy and Sarah.
A13: P12 | B13: VINE | D13: MOST LIKELY AT LEAST HALF AFRICAN | F13: CABARITTA ESTATE | G13: L8 | H13: Vine was a full blooded African or a first generation Afro-Creole domestic laborer who lived on a neighboring plantation called Cabaritta Estate owned by one of Thistlewood's friends, Samuel Say. She was the daughter of at least one enslaved African parent, a man named Old Pompey who belonged to another of Thistlewood's friends named Jeremiah Meyer and lived on his estate of Meylersfield. When Vine's mother died in 1764, the enslaved community held a "play" (a communal funeral) in her honor. Vine was involved in various sexual/domestic partnerships over the course of several years, including one with a white man named MacArthur who was employed on the Roaring River estate, and another with a driver named Sam who lived on the property of a Mrs. Sarah Bennett (who would lster sell thistlewood Breadnut Island Pen). The diary never describes Vine as having any children of her own. However, she was a regular presence in the lives of her friends' children, especially that of her friend Phibbah [the housekeeper of Egypt Estate) and Phibbah's children John and Accubah, and Egypt Lucy's child Little Quashe. Vine was a very close friend of Phibbah, Phibbah's sister Nancy, an enslaved domestic woman from Paradise Estate named House Franke, and an enslaved field woman from Egypt Estate named Egypt Lucy. Vine, Phibbah and John were relatively privileged as domestic laborers, given leave by their masters to attend various social events througout the parish such as horse races. In a significant departure from most other enslaved people in Jamica who were forced to walk everywhere as their chief means of transportation, Vine owned her own horse named Powder Tail. Vine was a skilled healer and regularly attended to the sickbeds of enslaved men, women and children when they were ill--especially when they were friends or her friends' children. Vine was a skilled teller of Anansi spider stories, and frequently came to Egypt in the evenings to tell them to enslaved people and whites alike, sometimes alongside other enslaved Africans like Abba.
A14: P13 | B14: OGO | C14: MARIA | D14: EBO | E14: 4'11 INCHES HIGH (1761) 'TT' IN DOWNWARD TRIANGLE BRAND ON HER RIGHT SHOULDER (1761) | F14: EGYPT ESTATE (1761-1767) BREADNUT ISLAND PEN (1767-1786) | G14: L1; L3 | H14: Ogo first appeared in the diary in December of 1761. Thistlewood purchased her in a group sale of five other Africans from a trader for 50 pounds. Upon her arrival to Egypt estate, he paired her with an enslaved fieldwoman named Egypt Lucy to be 'seasoned'. After renaming her "Maria," a mere one week after her purchase, he put Ogo to work in Egypt's fields. Five years after her arrival in Jamaica, Ogo gave birth to her first child: a daughter named Lucy. Her father was most likely Solon, an enslaved field laborer and sometimes driver whom Thistlewood purchased a few months before Ogo. Over the next several years, Ogo would have several more sexual partners/spouses, including another enslaved man at the neighboring Retrieve estate, an enslaved man named Peter owned by another of Thistlewood's friends named Wilson, and an enslaved man from Egypt estate named Cubbena. Thistlewood forced himself upon her sexually several times. The diary also confirms Ogo as having two more children: a boy born in 1770 who died at seven days old of tetanus, and another daughter named Rachael born in 1771 who would die in 1775 at four years old. Her eldest daughter, Lucy would fall sick of stomach pains and convulsions and die in 1777 at the age of ten. In the years following her captivity, Ogo would act as a nurse/caregiver for Abasse (renamed Will) when he became seriously ill and died in 1767, who was one of the six that Thistlewood purchased in 1761 and was thus likely one of Ogo's shipmates. Ogo outlived Thistlewood by the time of his death in 1786. In a 1787 appraisal of his human property, she was estimated to be "about 40 years old) and valued at 50 pounds (the exact same price Thistlewood orginally paid for her in 1761).
A15: P14 | B15: LUCY | C15: LITTLE LUCY | D15: AFRICAN/AT LEAST HALF EBO | F15: PARADISE ESTATE (1766) EGYPT ESTATE (1766-1767) BREADNUT ISLAND PEN (1767-1777) | G15: L2; L1; L3 | H15: Little Lucy was born in November of 1766 to Ogo, an "Ebo" young woman and fieldhand and Solon, an African young man and fieldhand on Paradise Estate, both purcahsed by Thistlewood in 1761. Her mother was assisted in the delivery by an enslaved grannie named Paradise Quasheba. Little Lucy would have two siblings: a brother born in 1770 who died at just seven days old of tetanus, and a younger sister, Rachael, born in 1771 and and who would die in 1775 at four years old. Little Lucy was often sick, and subject to frequent injuries over her life, but she often was able to recover. In 1777, she became extremely ill of stomach and neck pains for several days before falling into convulsions and dying at the age of ten--a milestone in a time and place when most enslaved children died before reaching the age of two. Solon dug her grave. On the evening of her burial, a moon/lunar rainbow appeared in the sky.
A16: P15 | B16: NANNY | D16: AFRICAN | F16: KINGSTON EGYPT ESTATE BREADNUT ISLAND PEN | G16: L19; L1; L3 | H16: Nanny was an enslaved African young woman purchased by John Cope on Thistlewood's behalf in July of 1761 in Kingston, alongside two other African men: Solon and Caesar, who were also most likely her shipmates. She was presumed to be 21 years old. Nanny had just one daughter, born in August of 1766 "in the height of bad weather" at a neighboring estate called Paradise. Nanny was assisted in the birth by an enslaved grannie named Paradise Quasheba. Her daughter was named Little Phibbah. In the Spring of 1768, Nanny was entrusted with caring for Molia's (renaned Coobah) only child Silvia while Molia was hired out to labor on a neighboring plantation. Silvia fell sick while her mother was away and died at 15 months old. Little Phibbah was often ill througnout her life, and in 1771 she died at age of five after a long and painful bout of stomach worms. Nanny would be one of the enslaved people on Breadnut Island Pen who would go on to outlive Thistlewood following his death in 1786. In a 1787 appraisal of his human property she was estimated to be "about 47 years old" and valued at 60 pounds.
A17: P16 | B17: COOBAH | C17: ACCUBBAH; JENNY YOUNG; PHIBBAH'S COOBAH | D17: ? | F17: PARADISE ESTATE | G17: L2 | H17: Accubah, also known as 'Coobah' was an enslaved Afro-Creole girl born to Phibbah, the housekeeper of Egypt Estate and an unknown father sometime during the 1750s. Throughout her childhood, she mostly lived apart from her mother on Paradise, a neighboring sugar estate that was also owned by their owners John and Mary (Molly) Copeand served as a domestic servant to Molly Cope. Accubah was later sent to a school for mixed race children at an early age to learn to read and write. In addition to being frequently separated from her mother, Accubah was frequently the target of sexual predation from white men, including John Cope and a white laborer on Egypt named Sam Matthews who attempted to rape her in Egypt's boiling house in before being thwarted, ironically enough, by Thistlewood himself. She was one of the only enslaved girls/women in the diary who he never forced himself upon sexually. Accubah had a number of sexual partners over the years who were mostly either free mixed race men of color, or white men. Three of the mixed race men were described as being her 'husband': Mulatto Davie in 1761, Nagua in 1766 (who also appeared to have grown up with Accubah on the estate), and Jimmy Stewart in 1776. Accubah was an accomplished seamstress, who put her skills to good use in taking on paid sewing jobs for Thistlewood, and also sewing intricate messages into the dresses and bodices of her fellow enslaved women. At some point during the late 1760's Accubah became involved in the cult society of Myalism; an Afro-Jamaican religion that according to what some scholars have argued was “the first religious organization of Africans in Jamaica” that “addressed itself to the entire slave society." Myal was organized around the premise that enslaved people could inure themselves to the many dangers and predations from white Accubah was very close with her mother PhIbbah, and with her mother Phibbah's friends: Accubah's aunt Nancy, an enslaved domestic woman who also lived at Paradise named House Franke, an enslaved domestic woman and healer named Vine from Cabaritta estate and an enslaved field woman from Egypt named Egypt Lucy. Together, the six women pooled the money and resources they earned through the selling of goods they raised from their provison grounds, their raising of livestock, and from sewing work they were contracted to perform for whites. They intended the funds to be used to purchase at least one of each other's freedom. Accubah was very fond of hearing Anansi spider tales told by her mother's close friend, an enslaved healer from Cabarittta Estate named Vine. She made regular trips to her mother's later residence of Breadnut Island Pen to hear them under the cover of night. Accubah traveled abroad to England twice in her lifetime; once in 1767 and once in the spring of 1771, as a domestic to the Cope's two daughters. On her second trip, she was baptized into the Church of England and christened 'Jenny Young', a name she would go by for the rest of her life after returning to Jamaica. Accubah had seversl children over the course of her life, but only one of whom would survive into childhood: Little Nancy (presumably named after her Aunt). Like her mother, Accubah/Jenny Young would go onto outlive Thistlewood past his death in 1786, although it is unknown whether or not she would ever receive her freedom like her mother did.
A18: P17 | B18: SALLY | D18: CONGO | E18: 4'1 INCHES HIGH (1762) | F18: BREADNUT ISLAND PEN | G18: L3 | H18: Sally first appears in the diary in April of 1762 in a purchase that Thistlewood made from one his white associates/friends Jeremiah Meyler. He described her as a "Congo girl" of no more than "9 or 10 years old" and standing at just 4'1 inches tall. He paid 42 pounds cash for her. Sally was originally intended and trained to be a seamstress/domestic laborer, but for the next twenty two years, she would put up regular and varied shows of resistance to every job, assignment or position that Thistlewood tried to force upon her. Even after he eventually relegated her to his field gang, Sally regularly stole food and other possessions from both white and endlsved Black people throughout the neighborhood. Over the course of her twenty two years in Jamaica, she ran away at least twelve different times. Sally was the victim of many acts of sexual assault and terrorism from various white men. (including Thistlewood) that mutilated her genitals, which probably attributed to the fact that she never had any children, nor was confirmed as ever being pregnant. Like many field laborers in Jamaica, she was often ill from yaws (which resulted in the amputation of one of her toes), and from venereal diseases. In November of 1784, Thistlewood sold Sally to anther trader, who transported her off the island altogether and to an unknown location.
A19: P18 | B19: PARADISE QUASHEBA | D19: ? | F19: PARADISE ESTATE | G19: L2 | H19: Paradise Quasheba was an enslaved 'grannie' (midwife) who lived on Paradise Estate. She attended at least eleven different enslaved women's births between 1759-1766: Egypt Lucy, Nancy, Rosanna, Moll, Agnes, Jenny, Wonga, Molia, Ogo, Nanny and Eve--the majority of whose infants survived both a 9 day observing period and several years into their childhoods.
A20: P19 | B20: PEGGY | D20: AFRICAN | E20: 5'1 INCHES HIGH SCAR ON LEFT CHEEK BACK AND BELLY FULL OF COUNTRY MARKS HOLES THROUGH HER NOSE (1765) 'TT' BRAND ON HER RIGHT SHOULDER SCARS FROM REPEATED FLOGGINGS | F20: BREADNUT ISLAND PEN | G20: L3 | H20: Peggy was an African young woman who first appeared in the diary in 1765 when Thistlewood attended a 'slave scramble' aboard a Guinea ship and purchased her alongside 9 other enslaved Africans (5 young men and 4 other young women in total). These 9 Africans were Peggy's shipmates: Syphox, Cudjoe, Chub, Bristol, Jmmy, Myrtilla, Phoebe, Franke and Damsel). Thistlewood presumed her to be "about 16 or 17 years old." Peggy was assigned to field labor for the next twenty one years. She was often ill of yaws. Thistlewood also speculated that at times, she showed signs of being "disordered in her senses," although he doesn't specify why/how. If Peggy ever had a husband/domestic partner, Thistlewood never knew or recorded it. She never bore any children, nor was she ever described as ever being pregnant. For several years, she shared a household with her fellow field gang member Molia [Coobah] and Molia's daughter, Silvia. Follwing Silvia's death, Peggy continued to share a household with Molia until 1774 when Thistlewood, frustrated with her repeated escaps attempts, sold her to a trader who trafficked her to Georgia. Peggy was caught engaging in geophagia (eating dirt) in 1774 and was flogged for it (notably for the first time). An accident involving a driver and a whip caused her right eye to be severely mutilated in June of 1780. She was one of the enslaved community who outlived Thistlewood following his death in 1786. In a 1787 appraisal, she was estimated to be about 39 years old, described as "distempered," "blind in one eye" and valued at 10 pounds.
A21: P20 | B21: ABBA'S JOHNIE | D21: AT LEAST HALF AFRICAN | F21: EGYPT ESTATE BREADNUT ISLAND PEN | G21: L1; L3 | H21: Johnie was born in 1764 to Abba, an enslaved African domestic laborer that Thistlewood first purchased in 1758. His father may have been Neptune, an enslaved man belonging to a white man named Emotson, one of Thistlewood's friends who also owned a tavern in Savanna la Mar and was described as Abba's "husband" around the time of his birth. He had three surviving siblings who: an elder sister named Mary, a younger brother named Neptune and a younger sister named Jenny. Johnie lived to the age of seven (a milestone for a child in Jamaica at that time). In January of 1771, he became deathly ill, suffering from stmach cramps and falling into "faints"/"fits" (seizures). Vine, an enslaved domestic laborer and healer from the neighboring Cabaritta estate came to "bleed" and tend to Johnie. Three days later Thistlewood himself sent Abba with Johnie to the parish Bay to be seen and treated by a white physician, but Johnie died on the trip back home. Abba was inconsolable with grief. Johnie was buried that same evening near his mother's house. Numerous enslaved people from surrounding estates and pens, including Vine, attended his funeral, singing over him. Several months later in July 1771, Abba was still in mourning for Johnie, engaging in the practice of 'throwing water' and participating in communal songs and drumming in his honor.
A22: P21 | B22: ABBA'S MARY | D22: AT LEAST HALF AFRICAN | F22: BREADNUT ISLAND PEN | G22: L2 | H22: Mary was born in January 1762, the first daughter/child of Abba, an African young woman and Neptune, an enslaved man belonging to a white man named Emotson, one of Thistlewood's friends who also owned a tavern in Savanna la Mar. She had three surviving siblings: Johnie, Neptune, and Jenny. In March/April of 1763, Mary contracted smallpox; though she ultimately recovered from the disease itself, she was permanently blinded. The diary describes Mary as having one husband/domestic partner on a neighboring sugar estate called Three Mile River named Quacoo with whom she had two children: one daughter born in 1784 who died at 1 week old, aand another daughter born in 1785 named Prue who was still alive by the time of Thistlewood's death inn 1786. Like her mother, Mary outlived Thistlewood. Inan appraisal of the complete inventory of all his human property, her value was estimated to be just 1 pound.
A23: P22 | B23: LITTLE PHIBBAH | D23: AT LEAST HALF AFRICAN | F23: PARADISE ESTATE EGYPT ESTATE BREADNUT ISLAND PEN | G23: L2; L1; L3 | H23: Little Phibbah was born in August 1766 at Paradise Estate in "the height of bad weather" to an enslaved African woman named Nanny and an unknown father. A midwife named Paradise Quasheba was in attendance at her birth. Little Phibbah was frequently ill and cared for by her mother. When she was five years old, she became very badly afflicted with stomach worms. After being treated repeatedly by her mother, Thistlewood and white physicians over the course of several days, she died on September 9 1771. Two enslaved men named Lincoln and Abasse dug her grave and buried her the next evening.
A24: P23 | B24: SHIPMATE | D24: AFRICAN | F24: BLUEFIELDS BAY | G24: L11 | H24: In November of 1770, an enslaved "Ebo" woman named Molia made her seventh esacpe from Breadnut Island Pen. She stayed missing for eleven days before being caught at a place called Bluefields Bay and brought back to the Pen. At some point during this recovery Molia told someone that she had gone to Bluefields Bay for a specific purpose; this purpose was to see a person she desccribed as her "shipmate". This unnamed/unidentified person was Molia's shipmate with whom she had, presumably, survived hte Middle Passage voyage at least nearly a decade earlier and with whom she had maintained a close and intimate relationship. It is the first and on;y time that this Shipmate would ever be mentioned in the diary.
A25: P24 | B25: LINCOLN | D25: EBO | F25: EGYPT ESTATE BREADNUT ISLAND PEN | G25: L1; L3 | H25: Lincoln first appears in the diary in Janury of 1756 as the very first enslaved person Thistlewood purchased for 43 pounds. Presumed to be an "Ebo", he was described as being 16 years of age, and 4 ft 9 inches tall. Throughout the course of those three decades, Thistlewood regularly appointed him to skilled positions such as a fisherman and a driver of the field gangs. He regularly entrusted him with the use and possession of a gun with which to hunt game and also regularly sent him out to search for and retrieve the most troublesome of runaways. Lincoln was the most frequent recipient of Thistlewood’s castoff clothes and worn possessions that he no longer wanted. The rations of food and rum he received were markedly higher than nearly everyone else’s. Lincoln had multiple domestic and sexual relationships, including one with an Egypt field woman named Violet, another named Egypt Susanah, and another African domestic laborer owned by Thistlewood named Abba. Lincoln and Abba would have two children together: a daughter named Jenny born in August of 1772, and a daughter named Phibbah born in April of 1776. Lincoln's longest core relationship however, was with Sukey, an African young woman who Thistlewood purchased in 1761 from a trader named John Hutt; they never had any children. Many of Lincoln's relationships with women were fraught with tension, even to the point of domestic violence. Lincoln would be one of the enslaved population on Breadnut Island Pen who would go on to outlive Thistlewood past his death in 1786. Presumed to be 47 years old in a 2787 appraisal, his value was assessed at 50 pounds.
A26: P25 | B26: MASON QUASHE | D26: ? | H26: Mason Quashe was an enslaved man who belonged to Elizabeth Anderson, a "free coloured (mixed race) woman"who was the mistress of William Dorrill, Thistlewood's first empoyer and the initial owner of Egypt, Salt River and Paradise upon his arrival in Jamaica. She frequently hired Mason Quashe out to Egypt and other estates throughout the parish where he performed a wide array of skilled and very highly sought after labors such as masonry, carpentry, fishing, and driving of the field gangs. He was 'paid' for these labors in rum and castoff clothing from white men. Mason Quashe was a prominent figure in the enslaved community of Westmoreland, and held close relationships with other prominent figures in that community such as Phibbah, the housekeeper of Egypt, and the other women in her social circle such as House Franke and Egypt Lucy, who tended/cared for him in times of illness. Mason Quashe had a number of sexual/domestic relationships with several enslaved women throughout the neighborhood, including one with Egypt field woman Egypt Lucy, who left her previous husband Daniel for him--their union rrsulted in a son born in December of 1759: Little Quashe. He also had another child, a daughter named Franke who lived on a neighboring estate. Mason Quashe's status as a skilled laborer seemed to give him a relative amount of privilege, particularly in his abilty to move around the parish, and beyond it. In 1767, he traveled abroad to British North America, where he would pass away from complications of gout and stomach maladies in 1767.
A27: P26 | B27: SOLON | D27: AFRICAN | F27: BREADNUT ISLAND PEN | G27: L3 | H27: Solon first appears in the diaries in July of 1761 when he was acquired by John Cope on Thistlewood's behalf from a slave market in Kingston alongside two others: an African woman named Nanny and an African young man named Caesar. Thistlewood paid 50 pounds for each one of them. He also described Solon as being "about 16". In later years, Solon would (like many others) be taken ill with various ailments and diseases such as stomach cramps, guinea worms, eye infections, and yaws. Solon was a skilled fisherman and was often sent by Thistlewood to catch fish for him in nearby rivers and streaams. He was also frequently sent out to search for escaped runaways, particularly a young 'Ebo' woman named Molia who ran away from Thistlewood at least 14 times between 1769-1774. Solon was the domestic partner/'husband' of Ogo (renamed 'Maria'), a presumed 'Ebo' African young woman purchased by Thistlewood from a slave trader named John Hutt in December of 1761. They had at least one child together: a daughter named Lucy, b0rn in November of 1766, who lived to the age of ten before dying in 1777 from stomach ailments.
A28: P27 | B28: WANGA | C28: PRINCESS | D28: AFRICAN | F28: EGYPT ESTATE | G28: L1 | H28: Wanga was an African woman who was purchased and brought to Egypt to work as field laborer in May of 1754 shortly after Thistlewood's arrival in the early 1750's. Upon her purchase, she was renamed "Princess," and paired with another enslaved woman named Quashe who served as her 'seasoner'. Wanga would have several confirmed sexual/domestic partners over the course of the sixteen years that Thistlewood served as overseer at Egypt. Among them were a driver named Hazat, and an Ebo man and skilled laborer named Cyrus, with whom she had a son in January of 1757 named Little Dick. Although he survived his first two years of life, Little Dick was badly afflicted with yaws, a severe bacterial infection that resulted in skin lesions, joint inflammation and bone pain/deformities. In July of 1759, Little Dick passed away from the complications of yaws. Two months later his father, Cyrus, would go on to hold a "feast" (funeral ceremony) in his honor. In 1761, Wanga was assigned to be the seasoner of an estimated 15 year old 'Ebo' young woman named Molia who had been purchased by Thistlewood and who he renamed 'Coobah'. Wanga ran away from the estate once in the spring of 1762. She was also pregnant at the time of her escape. Daniel, a skilled laborer was sent to search for and return her to the estate. She was later sent to Paradise estate to lie-in and give birth to a daughter named Charlotte, who survived at least until her second year.
A29: P28 | B29: OLD LEANDRA | D29: AFRICAN | F29: MRS. BENNETTS | H29: Old Leandra was an enslaved African woman and 'grannie' (midwife) who belonged to Sarah Bennett, a wealthy white proprietress who would later go on to sell Thistlewood Breadnut Island Pen in 1767. As a young(er) woman and captive upon a Middle Passage slave ship sailing from Guinea, Old Leandra was sexually coerced by the captain of the ship. She was alleged to have betrayed a plot of a shipboard rebellion to him in exchange for her freedom. Upon reaching Jamaica, the Captain temporarily left her in the keeping of a proprietor called Cunningham, supposedly as a "free person," until his return to reclaim her; he died while away. Neither Cunningham nor his son honored the agreement to give Old Leandra her freedom, and eventually sold her to Sarah Bennett, with whom she remained for many years. It would not be until 1772 when Old Leandra was an elderly woman and (presumably) of little to no further use to Sarah Bennett that Bennett abruptly announced to Old Leandra that she was at last free "to go where she pleases." The diary does not give a clear indication of where she lived following this 'release', but Old Leandra would go on to serve as a nurse and birthing attendant for Abba and Molia, two other women enslaved by Thistlewood. Old Leandra was a caregiver for enslaved children, most particularly for [Mulatto] John, the mixed race son of Thistlewood and Egypt's housekeeper Phibbah who lived with Sarah Bennett while attending a school for mixed race children.
A30: P29 | B30: JOB | D30: ? | F30: EGYPT ESTATE | G30: L1
A31: P30 | B31: MOUNTAIN LUCY | D31: ? | F31: EGYPT ESTATE | G31: L1 | H31: Mountain Lucy was an enslaved fieldwoman who lived and worked on Egypt estate from as early as 1754. Like many other fieldhands, Mountain Lucy lived in conditions of immense poverty and food scarcity. Throughout periods of particularly severe famine and droughts on the estate, she appeared to have engaged in a coercive sexual relationship with Thistlewood in exchange for food, "bitts" (money), and other presents. In 1755, when Egypt's domestic housekeeper Phibbah became pregnant, she "brought" Mountain Lucy to Thistlewood to "keep" as a "sweetheart" (sexual partner) while she was in her latter trimester of pregnancy. Thistlewood initially resisted the arrangement, but eventually relented. Mountain Lucy was the mother of at least four children. In 1756, she gave birth to a girl, Prue, who managed to survive at least until the age of 8 (an enormous milestone for enslaved chilren in Jamaica), and who Mountain Lucy claimed had been fathered by Thistlewood, presumably duringPhibbah';s lying in period (although he denied this). Between 1758 and 1759, she gave birth to two boys, once each year, who both died within days. Another girl, Flora would follow in 1761 and survive until at least the age of 3. Mountain Lucy ran away from the estate at least twice in 1756. She was found within days on both occasions and punished with brutal floggings and gaggings. She was also punished on multiple occasions for giving verbal protests to the drivers in the field
A32: P31 | B32: FANNY | D32: ?
A33: P32 | B33: MIRTILLA | C33: MYRTILLA | D33: SOCO | E33: TWO BLACK MARKS DESCENDING OBLIQUELY FROM HER EYES AND HER BELLY FULL OF COUNTRY MARKS | F33: EGYPT ESTATE | G33: L1
A34: P33 | B34: ELLIN | D34: EBO | F34: EGYPT ESTATE | G34: L1
A35: P34 | B35: DAMSEL | D35: CHAMBOY | E35: 4'8 INCHES HIGH ON HER FACE, 3 LONG STROKES DOWN EACH CHEEK, 2 SMALL OBLIQUE, ETC. HER BELLY FULL OF COUNTRY MARKS & AN IN ARCH BETWEEN HER BREASTS. (1765) | F35: BREADNUT ISLAND PEN | G35: L3
A36: P35 | B36: PARADISE JACK | D36: ? | F36: PARADISE ESTATE | G36: L2
A37: P36 | B37: OLD POMPEY | D37: MOST LIKELY AFRICAN
A38: P37 | B38: SUKEY | D38: AFRICAN | E38: 4'8 HIGH (1761) 'TT' IN DOWNWARD TRIANGLE BRAND ON HER RIGHT SHOULDER (1761) | F38: EGYPT ESTATE BREADNUT ISLAND PEN | G38: L1; L3
A39: P38 | B39: SAWNO; DOWOTRONNY | C39: DICK | D39: AFRICAN | E39: 5'7 HIGH (1761) "TT" IN DOWNWARD TRIANGLE BRAND ON HIS RIGHT SHOULDER | F39: EGYPT ESTATE BREADNUT ISLAND PEN | G39: L1; L3
A40: P39 | B40: ABASSE | C40: WILL | D40: EBO | E40: 5'3 HIGH (1761) "TT" IN DOWNWARD TRIANGLE BRAND ON HIS RIGHT SHOULDER | F40: EGYPT ESTATE BREADNUT ISLAND PEN | G40: L1; L3
...

Sheet EVENTS
A1: EVENT ID | B1: ARCHIVE ID(S) | C1: DATE(S) | D1: EVENT DESCRIPTION | E1: PERSON IDS | F1: NAMES | G1: PERSON IDS | H1: NAMES/PERSON IDS | I1: EVENT TYPE | J1: ALTERNATE NAMES | K1: LOCATION | L1: LOCATION ID | M1: VLOOKUP | N1: TIME OF DAY (AM/PM) | O1: WEATHER | P1: SPECIAL SKILL
A2: E34 | B2: IMG 150, P.294-295 | C2: May 2, 1750 | D2: "I think Port Royal has somewhat a grander look in the streets than Kingston" | E2: THE OVERSEER (P43) | F2: THE OVERSEER | G2: P43 | H2: =CONCATENATE(F2," (",G2,")") -> THE OVERSEER (P43) | I2: GEOGRAPHY/TERRAIN | J2: THOMAS THISTLEWOOD | K2: PORT ROYAL | L2: L25 | M2: =VLOOKUP(L2, GLOSSARY!$A:$C, 2, FALSE) -> PORT ROYAL | N2: AM
A3: E35 | B3: IMG 152, P.298-299 | C3: May 11, 1750 | D3: "Mr. Dorrill's house is pleasantly situated about 1/4 off [sic] a mile from the sea and about 2 1/2 or 3 mile from Savanna la Mar, to the east, paved with wood, backed with stone or more properly lined has port holes for deffence [sic]. Wood columns on East side near Salt River." | E3: THE OVERSEER (P43) | F3: THE OVERSEER | G3: P43 | H3: =CONCATENATE(F3," (",G3,")") -> THE OVERSEER (P43) | I3: GEOGRAPHY/TERRAIN | J3: THOMAS THISTLEWOOD | K3: SALT RIVER ESTATE | L3: L4 | M3: =VLOOKUP(L3, GLOSSARY!$A:$C, 2, FALSE) -> SALT RIVER ESTATE | N3: AM
A4: E36 | B4: IMG 152, P.298-299 | C4: May 15, 1750 | D4: "Many runaway Negroes took up, Mr. Dorrill had his own whipp'd severely and rubb'd with pepper, salt, and lime juice." | E4: WILLIAM DORRILL (P75) | F4: WILLIAM DORRILL | G4: P75 | H4: =CONCATENATE(F4," (",G4,")") -> WILLIAM DORRILL (P75) | I4: PUNISHMENT/VIOLENCE | K4: SALT RIVER ESTATE | L4: L4 | M4: =VLOOKUP(L4, GLOSSARY!$A:$C, 2, FALSE) -> SALT RIVER ESTATE
A5: E37 | B5: IMG 152, P.298-299 | C5: May 15, 1750 | D5: "20 acres planted with logwood seed, and well minded, in 20 years time or less, would be a pretty fortune for a man." | H5: =CONCATENATE(F5," (",G5,")") -> () | I5: GARDENING/AGRICULTURE | K5: SALT RIVER ESTATE | L5: L4 | M5: =VLOOKUP(L5, GLOSSARY!$A:$C, 2, FALSE) -> SALT RIVER ESTATE
A6: E41 | B6: IMG 153, P.300-301 | C6: May 18, 1750 | D6: "Yesterday a runaway Negroe being dead and buried while we were away. Mr. Dorrill caused him to be took up, his head stuck upon a pole and his body burnt." | E6: WILLIAM DORRILL (P75) | F6: WILLIAM DORRILL | G6: P75 | H6: =CONCATENATE(F6," (",G6,")") -> WILLIAM DORRILL (P75) | I6: PUNISHMENT/VIOLENCE | K6: SALT RIVER ESTATE | L6: L4 | M6: =VLOOKUP(L6, GLOSSARY!$A:$C, 2, FALSE) -> SALT RIVER ESTATE | N6: AM
A7: E44 | B7: IMG 153, P.300-301 | C7: May 18, 1750 | D7: "surveyors ought to avoid pitching their forts near old trees, which frequently fall and make great havoc. Many deep and frightful cockpitts in the mountains." | E7: THE OVERSEER (P43) | F7: THE OVERSEER | G7: P43 | H7: =CONCATENATE(F7," (",G7,")") -> THE OVERSEER (P43) | I7: GEOGRAPHY/TERRAIN | K7: WILDERNESS | L7: L15 | M7: =VLOOKUP(L7, GLOSSARY!$A:$C, 2, FALSE) -> WILDERNESS | N7: AM
A8: E40 | B8: IMG 154, P.302-303 | C8: May 24, 1750 | D8: "All day running off lines in the Black Morass to adjust hte bounds off Mr. Bernard Senior's lands, saw a very large yellow snake speckled upon the back! Several Black snakes and a very ugly large toad upon the back of a tree about 4 foot from the ground." | E8: THE OVERSEER (P43) | F8: THE OVERSEER | G8: P43 | H8: =CONCATENATE(F8," (",G8,")") -> THE OVERSEER (P43) | I8: HUSBANDRY/LIVESTOCK/FISHING | J8: THOMAS THISTLEWOOD | K8: SALT RIVER ESTATE | L8: L4 | M8: =VLOOKUP(L8, GLOSSARY!$A:$C, 2, FALSE) -> SALT RIVER ESTATE | N8: AM
A9: E32 | B9: IMG 155, P.304-305 | C9: May 30, 1750 | D9: "Killed a large Black snake." | E9: THE OVERSEER (P43) | F9: THE OVERSEER | G9: P43 | H9: =CONCATENATE(F9," (",G9,")") -> THE OVERSEER (P43) | I9: HUSBANDRY/LIVESTOCK/FISHING | J9: THOMAS THISTLEWOOD | K9: VINEYARD PEN | L9: L20 | M9: =VLOOKUP(L9, GLOSSARY!$A:$C, 2, FALSE) -> VINEYARD PEN
A10: E33 | B10: IMG 155, P.304-305 | C10: May 31, 1750 | D10: "Killed a very large Black snake." | E10: THE OVERSEER (P43) | F10: THE OVERSEER | G10: P43 | H10: =CONCATENATE(F10," (",G10,")") -> THE OVERSEER (P43) | I10: HUSBANDRY/LIVESTOCK/FISHING | J10: THOMAS THISTLEWOOD | K10: VINEYARD PEN | L10: L20 | M10: =VLOOKUP(L10, GLOSSARY!$A:$C, 2, FALSE) -> VINEYARD PEN
A11: E33 | B11: IMG 155, P.304-305 | C11: May 31, 1750 | D11: "Slept last night in a hamack [sick] in a hutt on Mr, Dorrill's plantation walk...Old Sharper (Mrs Elizabeth Anderson's Negroe) a clever old fellow looks after it." | E11: THE OVERSEER (P43) | F11: THE OVERSEER OLD SHARPER | G11: P43 | H11: =CONCATENATE(F11," (",G11,")") -> THE OVERSEER OLD SHARPER (P43) | I11: MISCELLANEOUS | J11: THOMAS THISTLEWOOD | K11: SALT RIVER ESTATE | L11: L4 | M11: =VLOOKUP(L11, GLOSSARY!$A:$C, 2, FALSE) -> SALT RIVER ESTATE | N11: PM
A12: E42 | B12: IMG 155, P.304-305 | C12: June 1, 1750 | D12: "Between 8 and 9 miles from Dean's Valley, met Colonel Cudjew [sic], one of his wives, one of his sons, a Lieutenant, and other attendants. He shook me by the hand, and Begg'd a dram of us which we gave him. He had on a feathered hat, sword by his side, gun upon his shoulder & barefoot and Bare legged. Somewhat a majestic look. He brought to my memory the picture of Robinson Crusoe." | E12: COLONEL CUDJOE (P78) THE OVERSEER (P43) | F12: COLONEL CUDJOE THE OVERSEER | G12: P78 P43 | H12: =CONCATENATE(F12," (",G12,")") -> COLONEL CUDJOE THE OVERSEER (P78 P43) | I12: MAROONS/MARRONAGE | K12: WILDERNESS | L12: L15 | M12: =VLOOKUP(L12, GLOSSARY!$A:$C, 2, FALSE) -> WILDERNESS | N12: AM
A13: E43 | B13: IMG 155, P.304-305 | C13: June 1, 1750 | D13: "We got to Great River about 2 in the afternoon, which is a little above 11 1/4 miles from Dean's Valley. Great River is about 40 yards wide at the wath and 30 in other place. I bath'd in it. Here are the largest, finest limes I ever saw." | E13: THE OVERSEER (P43) | F13: THE OVERSEER | G13: P43 | H13: =CONCATENATE(F13," (",G13,")") -> THE OVERSEER (P43) | I13: GARDENING/AGRICULTURE | K13: WILDERNESS | L13: L15 | M13: =VLOOKUP(L13, GLOSSARY!$A:$C, 2, FALSE) -> WILDERNESS | N13: AM
A14: E43 | B14: IMG 155, P.304-305 | C14: June 1, 1750 | D14: "Din'd at Barracks, catt leapt up to catch swallows, saw many unknown trees, forests, etc...Reached the plantane walk before night, where are lay again, eat some clocking in Broth and pepper pott with Old Sharper, who is a sensible NEgroe and also some Tumtum of plantanes and fish beat together." | E14: THE OVERSEER (P43) OLD SHARPER (P74) | F14: THE OVERSEER OLD SHARPER | G14: P43 P74 | H14: =CONCATENATE(F14," (",G14,")") -> THE OVERSEER OLD SHARPER (P43 P74) | I14: GARDENING/AGRICULTURE | K14: WILDERNESS | L14: L15 | M14: =VLOOKUP(L14, GLOSSARY!$A:$C, 2, FALSE) -> WILDERNESS | N14: AM/PM
A15: E39 | B15: IMG 156, P.306-307 | C15: June 2, 1750 | D15: "At 4PM the smartest clap of thunder heard for many years, nor 2 pulsations after the lightning, I having at that time my finger upon my pulse.:" | E15: THE OVERSEER (P43) | F15: THE OVERSEER | G15: P43 | H15: =CONCATENATE(F15," (",G15,")") -> THE OVERSEER (P43) | I15: WEATHER | J15: THOMAS THISTLEWOOD | K15: SALT RIVER ESTATE | L15: L20 | M15: =VLOOKUP(L15, GLOSSARY!$A:$C, 2, FALSE) -> VINEYARD PEN | N15: PM
A16: E31 | B16: IMG230, P.391-392 | C16: October 2, 1750 | D16: "Saw a Negroe fellow nam'd English belonging to Fellerswood tried, cast, and hang's upon the 1st tree immediately for drawing his knife upon a white man, his hand cutt off, Body left unbury'd." | H16: =CONCATENATE(F16," (",G16,")") -> () | I16: PUNISHMENT/VIOLENCE | K16: VINEYARD PEN | L16: L20 | M16: =VLOOKUP(L16, GLOSSARY!$A:$C, 2, FALSE) -> VINEYARD PEN | N16: AM
A17: E30 | B17: IMG 238, P.401-402 | C17: October 31, 1750 | D17: "Wanicker says, in the ship she was brought over in it was agreed to rise, but they were discovered first. The pickaninnys brought the men that were confined knives, muskets & other weapons." | E17: WANICKER (P73) | F17: WANICKER | G17: P73 | H17: =CONCATENATE(F17," (",G17,")") -> WANICKER (P73) | I17: REBELLION/UPRISING | K17: VINEYARD PEN | L17: L20 | M17: =VLOOKUP(L17, GLOSSARY!$A:$C, 2, FALSE) -> VINEYARD PEN
A18: E46 | B18: IMG 258, P.531-532 | C18: December 25, 1750 | D18: "At night had Creolian, Congo and Coromantian etc Musick & dancing enough. Egg cordial plenty." | E18: THE OVERSEER (P43) | F18: THE OVERSEER | G18: P73 | H18: =CONCATENATE(F18," (",G18,")") -> THE OVERSEER (P73) | I18: RECREATION | K18: SALT RIVER ESTATE | L18: L4 | M18: =VLOOKUP(L18, GLOSSARY!$A:$C, 2, FALSE) -> SALT RIVER ESTATE | N18: PM
A19: E375 | B19: IMG 5, P.6-7 | C19: January 8, 1751 | D19: "Mr. Barton's story of a Barbadoes woman that was rap'd by three of them (at Kingston) in a short spruce, he the middle man yet she laid up bastard child to him and how he madde her explain himself." | F19: MR. BARTON BARBADOS WOMAN | G19: P305 P306 | H19: =CONCATENATE(F19,"(",G19,")") -> MR. BARTON BARBADOS WOMAN(P305 P306) | I19: PUNISHMENT/VIOLENCE | L19: L20 | M19: =VLOOKUP(L19, GLOSSARY!$A:$C, 2, FALSE) -> VINEYARD PEN | N19: AM
A20: E376 | B20: IMG 8, P.12-15 | C20: January 21, 1751 | D20: "Alligators in the night make a noise catchign mosquitos etc with their mouths, like clapping their hands pretty much." | H20: =CONCATENATE(F20,"(",G20,")") -> () | I20: MISCELLANEOUS | L20: L20 | M20: =VLOOKUP(L20, GLOSSARY!$A:$C, 2, FALSE) -> VINEYARD PEN | N20: PM
A21: E378 | B21: IMG 10, P.16-17 | C21: January 28, 1751 | D21: "Negroes, etc believe if you hurt a carrion crow or her eggs...that you will never be well, thill they be well, spoil'd or dead. Another piece of superstition amongst them, is that they imagine glass bottles and images they cutt in wood, etc, can tell them, who thieves anyting out of the ground where they are sett up, or stuck. *some throw dry rotten wood upon water to drop shatt (?), some make the water thick with cow dung, others dtop into (?) but out upon the water is best. Barton's Dick Negroes say, the powder of ratt stones dried and sprinkled upon anything and given to women you want, forces her to desire you." | F21: BARTON'S DICK | G21: P308 | H21: =CONCATENATE(F21,"(",G21,")") -> BARTON'S DICK(P308) | I21: SUPERSTITION | L21: L20 | M21: =VLOOKUP(L21, GLOSSARY!$A:$C, 2, FALSE) -> VINEYARD PEN | N21: AM
A22: E377 | B22: IMG 12, P.20-21 | C22: February 4, 1751 | D22: "Beneba gone to wash in the sea." | F22: BENEBA | G22: P307 | H22: =CONCATENATE(F22,"(",G22,")") -> BENEBA(P307) | I22: RECREATION | L22: L53 | M22: =VLOOKUP(L22, GLOSSARY!$A:$C, 2, FALSE) -> THE SEA | N22: AM
A23: E38 | B23: IMG 35, P.60A-61A | C23: April 18, 1751 | D23: "About 12 at night cum Cynthia alias Nacomma sup lect Matt in supio domo parlor. * She is a Bambarah Negroes call Crippah or Tinnedones, being brought into their country young." | E23: NACOMMA (P77) THE OVERSEER (P43) | F23: NACOMMA THE OVERSEER | G23: P77 P43 | H23: =CONCATENATE(F23," (",G23,")") -> NACOMMA THE OVERSEER (P77 P43) | I23: SEX | K23: SALT RIVER ESTATE | L23: L20 | M23: =VLOOKUP(L23, GLOSSARY!$A:$C, 2, FALSE) -> VINEYARD PEN | N23: PM
A24: E379 | B24: IMG 53, P.90-91 | C24: June 1, 1751 | D24: "Negroes won't sweep this house at night, however dirty, for say they, it will occasion them to have ill luck." | H24: =CONCATENATE(F24,"(",G24,")") -> () | I24: SUPERSTITION | L24: L20 | M24: =VLOOKUP(L24, GLOSSARY!$A:$C, 2, FALSE) -> VINEYARD PEN | N24: PM
A25: E380 | B25: IMG 54, P.92-93 | C25: June 5, 1751 | D25: "In the afternoon, Phibbah and Scipio go out wiht cloath, gave Phibbah a tickett that she may not be molested, thus: Vineyard Penn June 5, 1751 The bearer herself (a Negroe man and woman nam'd Scipio and Phbbah) in company, belong to the The Vineyard Penn and the property of Florentius Vassall, Esq by whose orders they go out wiht cloath to sell which is certigied by me, Thomas Thistlewood." | F25: VINEYARD PHIBBAH SCIPIO | G25: P309 P310 | H25: =CONCATENATE(F25,"(",G25,")") -> VINEYARD PHIBBAH SCIPIO(P309 P310) | I25: HIGGLING/PROVISION | L25: L12 | M25: =VLOOKUP(L25, GLOSSARY!$A:$C, 2, FALSE) -> THE ROAD(S) | N25: AM
A26: E380 | B26: IMG 55, P.94-95 | C26: June 7, 1751 | D26: "Hugo sick, Phibbah and Scipio out with cloath." | F26: HUGO VINEYARD PHIBBAH SCIPIO | G26: P309 P310 P311 | H26: =CONCATENATE(F26,"(",G26,")") -> HUGO VINEYARD PHIBBAH SCIPIO(P309 P310 P311) | I26: HIGGLING/PROVISION | L26: L12 | M26: =VLOOKUP(L26, GLOSSARY!$A:$C, 2, FALSE) -> THE ROAD(S)
